=== tests/cases/compiler/overloadsWithProvisionalErrors.ts ===
var func: {
>func : { (s: 文字): 数字; (lambda: (s: 文字) => { a: 数字; b: 数字; }): 文字; }

    (s: string): number;
>s : 文字
>类型别名 :=> 文字

    (lambda: (s: string) => { a: number; b: number }): string;
>lambda : (s: 文字) => { a: 数字; b: 数字; }
>s : 文字
>类型别名 :=> 文字
>a : 数字
>类型别名 :=> 数字
>b : 数字
>类型别名 :=> 数字

};

func(s => ({})); // Error for no applicable overload (object type is missing a and b)
>func(s => ({})) : 任意
>类型别名 :=> 任意
>func : { (s: 文字): 数字; (lambda: (s: 文字) => { a: 数字; b: 数字; }): 文字; }
>s => ({}) : (s: 文字) => {}
>s : 文字
>类型别名 :=> 文字
>({}) : {}
>{} : {}

func(s => ({ a: blah, b: 3 })); // Only error inside the function, but not outside (since it would be applicable if not for the provisional error)
>func(s => ({ a: blah, b: 3 })) : 文字
>类型别名 :=> 文字
>func : { (s: 文字): 数字; (lambda: (s: 文字) => { a: 数字; b: 数字; }): 文字; }
>s => ({ a: blah, b: 3 }) : (s: 文字) => { a: 任意; b: 数字; }
>s : 文字
>类型别名 :=> 文字
>({ a: blah, b: 3 }) : { a: 任意; b: 数字; }
>{ a: blah, b: 3 } : { a: 任意; b: 数字; }
>a : 任意
>类型别名 :=> 任意
>blah : 任意
>类型别名 :=> 任意
>b : 数字
>类型别名 :=> 数字
>3 : 3

func(s => ({ a: blah })); // Two errors here, one for blah not being defined, and one for the overload since it would not be applicable anyway
>func(s => ({ a: blah })) : 任意
>类型别名 :=> 任意
>func : { (s: 文字): 数字; (lambda: (s: 文字) => { a: 数字; b: 数字; }): 文字; }
>s => ({ a: blah }) : (s: 文字) => { a: 任意; }
>s : 文字
>类型别名 :=> 文字
>({ a: blah }) : { a: 任意; }
>{ a: blah } : { a: 任意; }
>a : 任意
>类型别名 :=> 任意
>blah : 任意
>类型别名 :=> 任意

